2023-01-26 01:22:49,021 -  nornir.core -     INFO -        run() - Running task 'hello_world' with args {} on 1 hosts
2023-01-26 01:29:20,595 -  nornir.core -  WARNING -        run() - Task 'hello_world' has not been run â€“ 0 hosts selected
2023-01-26 10:40:15,215 -  nornir.core -     INFO -        run() - Running task 'send_command' with args {'command': 'show version'} on 1 hosts
2023-01-26 10:40:30,262 - nornir.core.task -    ERROR -      start() - Host 'cat9k-test-ztp': task 'send_command' failed with traceback:
Traceback (most recent call last):
  File "/usr/local/lib/python3.10/site-packages/nornir/core/task.py", line 99, in start
    r = self.task(self, **self.params)
  File "/usr/local/lib/python3.10/site-packages/nornir_scrapli/tasks/core/send_command.py", line 36, in send_command
    scrapli_conn = task.host.get_connection("scrapli", task.nornir.config)
  File "/usr/local/lib/python3.10/site-packages/nornir/core/inventory.py", line 494, in get_connection
    self.open_connection(
  File "/usr/local/lib/python3.10/site-packages/nornir/core/inventory.py", line 546, in open_connection
    conn_obj.open(
  File "/usr/local/lib/python3.10/site-packages/nornir_scrapli/connection.py", line 105, in open
    connection.open()
  File "/usr/local/lib/python3.10/site-packages/scrapli/driver/base/sync_driver.py", line 88, in open
    self.channel.channel_authenticate_ssh(
  File "/usr/local/lib/python3.10/site-packages/scrapli/decorators.py", line 216, in decorate
    return _multiprocessing_timeout(
  File "/usr/local/lib/python3.10/site-packages/scrapli/decorators.py", line 113, in _multiprocessing_timeout
    return future.result()
  File "/usr/local/Cellar/python@3.10/3.10.9/Frameworks/Python.framework/Versions/3.10/lib/python3.10/concurrent/futures/_base.py", line 451, in result
    return self.__get_result()
  File "/usr/local/Cellar/python@3.10/3.10.9/Frameworks/Python.framework/Versions/3.10/lib/python3.10/concurrent/futures/_base.py", line 403, in __get_result
    raise self._exception
  File "/usr/local/Cellar/python@3.10/3.10.9/Frameworks/Python.framework/Versions/3.10/lib/python3.10/concurrent/futures/thread.py", line 58, in run
    result = self.fn(*self.args, **self.kwargs)
  File "/usr/local/lib/python3.10/site-packages/scrapli/channel/sync_channel.py", line 290, in channel_authenticate_ssh
    self._ssh_message_handler(output=authenticate_buf)
  File "/usr/local/lib/python3.10/site-packages/scrapli/channel/base_channel.py", line 432, in _ssh_message_handler
    raise ScrapliAuthenticationFailed(msg)
scrapli.exceptions.ScrapliAuthenticationFailed: Timed out connecting to host

2023-01-26 10:41:06,378 -  nornir.core -     INFO -        run() - Running task 'send_command' with args {'command': 'show version'} on 1 hosts
2023-01-26 10:41:06,435 - nornir.core.task -    ERROR -      start() - Host 'cat9k-test-ztp': task 'send_command' failed with traceback:
Traceback (most recent call last):
  File "/usr/local/lib/python3.10/site-packages/scrapli/transport/plugins/system/transport.py", line 158, in read
    buf = self.session.read(65535)
  File "/usr/local/lib/python3.10/site-packages/scrapli/transport/plugins/system/ptyprocess.py", line 496, in read
    raise EOFError("End Of File (EOF). Empty string style platform.")
EOFError: End Of File (EOF). Empty string style platform.

The above exception was the direct cause of the following exception:

Traceback (most recent call last):
  File "/usr/local/lib/python3.10/site-packages/nornir/core/task.py", line 99, in start
    r = self.task(self, **self.params)
  File "/usr/local/lib/python3.10/site-packages/nornir_scrapli/tasks/core/send_command.py", line 36, in send_command
    scrapli_conn = task.host.get_connection("scrapli", task.nornir.config)
  File "/usr/local/lib/python3.10/site-packages/nornir/core/inventory.py", line 494, in get_connection
    self.open_connection(
  File "/usr/local/lib/python3.10/site-packages/nornir/core/inventory.py", line 546, in open_connection
    conn_obj.open(
  File "/usr/local/lib/python3.10/site-packages/nornir_scrapli/connection.py", line 105, in open
    connection.open()
  File "/usr/local/lib/python3.10/site-packages/scrapli/driver/base/sync_driver.py", line 88, in open
    self.channel.channel_authenticate_ssh(
  File "/usr/local/lib/python3.10/site-packages/scrapli/decorators.py", line 216, in decorate
    return _multiprocessing_timeout(
  File "/usr/local/lib/python3.10/site-packages/scrapli/decorators.py", line 113, in _multiprocessing_timeout
    return future.result()
  File "/usr/local/Cellar/python@3.10/3.10.9/Frameworks/Python.framework/Versions/3.10/lib/python3.10/concurrent/futures/_base.py", line 451, in result
    return self.__get_result()
  File "/usr/local/Cellar/python@3.10/3.10.9/Frameworks/Python.framework/Versions/3.10/lib/python3.10/concurrent/futures/_base.py", line 403, in __get_result
    raise self._exception
  File "/usr/local/Cellar/python@3.10/3.10.9/Frameworks/Python.framework/Versions/3.10/lib/python3.10/concurrent/futures/thread.py", line 58, in run
    result = self.fn(*self.args, **self.kwargs)
  File "/usr/local/lib/python3.10/site-packages/scrapli/channel/sync_channel.py", line 287, in channel_authenticate_ssh
    buf = self.read()
  File "/usr/local/lib/python3.10/site-packages/scrapli/channel/sync_channel.py", line 69, in read
    buf = self.transport.read()
  File "/usr/local/lib/python3.10/site-packages/scrapli/decorators.py", line 216, in decorate
    return _multiprocessing_timeout(
  File "/usr/local/lib/python3.10/site-packages/scrapli/decorators.py", line 113, in _multiprocessing_timeout
    return future.result()
  File "/usr/local/Cellar/python@3.10/3.10.9/Frameworks/Python.framework/Versions/3.10/lib/python3.10/concurrent/futures/_base.py", line 451, in result
    return self.__get_result()
  File "/usr/local/Cellar/python@3.10/3.10.9/Frameworks/Python.framework/Versions/3.10/lib/python3.10/concurrent/futures/_base.py", line 403, in __get_result
    raise self._exception
  File "/usr/local/Cellar/python@3.10/3.10.9/Frameworks/Python.framework/Versions/3.10/lib/python3.10/concurrent/futures/thread.py", line 58, in run
    result = self.fn(*self.args, **self.kwargs)
  File "/usr/local/lib/python3.10/site-packages/scrapli/transport/plugins/system/transport.py", line 165, in read
    raise ScrapliConnectionError(msg) from exc
scrapli.exceptions.ScrapliConnectionError: encountered EOF reading from transport; typically means the device closed the connection

2023-01-26 10:41:19,040 -  nornir.core -     INFO -        run() - Running task 'send_command' with args {'command': 'show version'} on 1 hosts
2023-01-26 10:41:19,085 - nornir.core.task -    ERROR -      start() - Host 'cat9k-test-ztp': task 'send_command' failed with traceback:
Traceback (most recent call last):
  File "/usr/local/lib/python3.10/site-packages/scrapli/transport/plugins/system/transport.py", line 158, in read
    buf = self.session.read(65535)
  File "/usr/local/lib/python3.10/site-packages/scrapli/transport/plugins/system/ptyprocess.py", line 496, in read
    raise EOFError("End Of File (EOF). Empty string style platform.")
EOFError: End Of File (EOF). Empty string style platform.

The above exception was the direct cause of the following exception:

Traceback (most recent call last):
  File "/usr/local/lib/python3.10/site-packages/nornir/core/task.py", line 99, in start
    r = self.task(self, **self.params)
  File "/usr/local/lib/python3.10/site-packages/nornir_scrapli/tasks/core/send_command.py", line 36, in send_command
    scrapli_conn = task.host.get_connection("scrapli", task.nornir.config)
  File "/usr/local/lib/python3.10/site-packages/nornir/core/inventory.py", line 494, in get_connection
    self.open_connection(
  File "/usr/local/lib/python3.10/site-packages/nornir/core/inventory.py", line 546, in open_connection
    conn_obj.open(
  File "/usr/local/lib/python3.10/site-packages/nornir_scrapli/connection.py", line 105, in open
    connection.open()
  File "/usr/local/lib/python3.10/site-packages/scrapli/driver/base/sync_driver.py", line 88, in open
    self.channel.channel_authenticate_ssh(
  File "/usr/local/lib/python3.10/site-packages/scrapli/decorators.py", line 216, in decorate
    return _multiprocessing_timeout(
  File "/usr/local/lib/python3.10/site-packages/scrapli/decorators.py", line 113, in _multiprocessing_timeout
    return future.result()
  File "/usr/local/Cellar/python@3.10/3.10.9/Frameworks/Python.framework/Versions/3.10/lib/python3.10/concurrent/futures/_base.py", line 451, in result
    return self.__get_result()
  File "/usr/local/Cellar/python@3.10/3.10.9/Frameworks/Python.framework/Versions/3.10/lib/python3.10/concurrent/futures/_base.py", line 403, in __get_result
    raise self._exception
  File "/usr/local/Cellar/python@3.10/3.10.9/Frameworks/Python.framework/Versions/3.10/lib/python3.10/concurrent/futures/thread.py", line 58, in run
    result = self.fn(*self.args, **self.kwargs)
  File "/usr/local/lib/python3.10/site-packages/scrapli/channel/sync_channel.py", line 287, in channel_authenticate_ssh
    buf = self.read()
  File "/usr/local/lib/python3.10/site-packages/scrapli/channel/sync_channel.py", line 69, in read
    buf = self.transport.read()
  File "/usr/local/lib/python3.10/site-packages/scrapli/decorators.py", line 216, in decorate
    return _multiprocessing_timeout(
  File "/usr/local/lib/python3.10/site-packages/scrapli/decorators.py", line 113, in _multiprocessing_timeout
    return future.result()
  File "/usr/local/Cellar/python@3.10/3.10.9/Frameworks/Python.framework/Versions/3.10/lib/python3.10/concurrent/futures/_base.py", line 451, in result
    return self.__get_result()
  File "/usr/local/Cellar/python@3.10/3.10.9/Frameworks/Python.framework/Versions/3.10/lib/python3.10/concurrent/futures/_base.py", line 403, in __get_result
    raise self._exception
  File "/usr/local/Cellar/python@3.10/3.10.9/Frameworks/Python.framework/Versions/3.10/lib/python3.10/concurrent/futures/thread.py", line 58, in run
    result = self.fn(*self.args, **self.kwargs)
  File "/usr/local/lib/python3.10/site-packages/scrapli/transport/plugins/system/transport.py", line 165, in read
    raise ScrapliConnectionError(msg) from exc
scrapli.exceptions.ScrapliConnectionError: encountered EOF reading from transport; typically means the device closed the connection

2023-01-26 10:44:35,704 -  nornir.core -     INFO -        run() - Running task 'send_command' with args {'command': 'show version'} on 1 hosts
2023-01-26 10:44:35,787 - nornir.core.task -    ERROR -      start() - Host 'cat9k-test-ztp': task 'send_command' failed with traceback:
Traceback (most recent call last):
  File "/usr/local/lib/python3.10/site-packages/scrapli/transport/plugins/system/transport.py", line 158, in read
    buf = self.session.read(65535)
  File "/usr/local/lib/python3.10/site-packages/scrapli/transport/plugins/system/ptyprocess.py", line 496, in read
    raise EOFError("End Of File (EOF). Empty string style platform.")
EOFError: End Of File (EOF). Empty string style platform.

The above exception was the direct cause of the following exception:

Traceback (most recent call last):
  File "/usr/local/lib/python3.10/site-packages/nornir/core/task.py", line 99, in start
    r = self.task(self, **self.params)
  File "/usr/local/lib/python3.10/site-packages/nornir_scrapli/tasks/core/send_command.py", line 36, in send_command
    scrapli_conn = task.host.get_connection("scrapli", task.nornir.config)
  File "/usr/local/lib/python3.10/site-packages/nornir/core/inventory.py", line 494, in get_connection
    self.open_connection(
  File "/usr/local/lib/python3.10/site-packages/nornir/core/inventory.py", line 546, in open_connection
    conn_obj.open(
  File "/usr/local/lib/python3.10/site-packages/nornir_scrapli/connection.py", line 105, in open
    connection.open()
  File "/usr/local/lib/python3.10/site-packages/scrapli/driver/base/sync_driver.py", line 88, in open
    self.channel.channel_authenticate_ssh(
  File "/usr/local/lib/python3.10/site-packages/scrapli/decorators.py", line 216, in decorate
    return _multiprocessing_timeout(
  File "/usr/local/lib/python3.10/site-packages/scrapli/decorators.py", line 113, in _multiprocessing_timeout
    return future.result()
  File "/usr/local/Cellar/python@3.10/3.10.9/Frameworks/Python.framework/Versions/3.10/lib/python3.10/concurrent/futures/_base.py", line 451, in result
    return self.__get_result()
  File "/usr/local/Cellar/python@3.10/3.10.9/Frameworks/Python.framework/Versions/3.10/lib/python3.10/concurrent/futures/_base.py", line 403, in __get_result
    raise self._exception
  File "/usr/local/Cellar/python@3.10/3.10.9/Frameworks/Python.framework/Versions/3.10/lib/python3.10/concurrent/futures/thread.py", line 58, in run
    result = self.fn(*self.args, **self.kwargs)
  File "/usr/local/lib/python3.10/site-packages/scrapli/channel/sync_channel.py", line 287, in channel_authenticate_ssh
    buf = self.read()
  File "/usr/local/lib/python3.10/site-packages/scrapli/channel/sync_channel.py", line 69, in read
    buf = self.transport.read()
  File "/usr/local/lib/python3.10/site-packages/scrapli/decorators.py", line 216, in decorate
    return _multiprocessing_timeout(
  File "/usr/local/lib/python3.10/site-packages/scrapli/decorators.py", line 113, in _multiprocessing_timeout
    return future.result()
  File "/usr/local/Cellar/python@3.10/3.10.9/Frameworks/Python.framework/Versions/3.10/lib/python3.10/concurrent/futures/_base.py", line 451, in result
    return self.__get_result()
  File "/usr/local/Cellar/python@3.10/3.10.9/Frameworks/Python.framework/Versions/3.10/lib/python3.10/concurrent/futures/_base.py", line 403, in __get_result
    raise self._exception
  File "/usr/local/Cellar/python@3.10/3.10.9/Frameworks/Python.framework/Versions/3.10/lib/python3.10/concurrent/futures/thread.py", line 58, in run
    result = self.fn(*self.args, **self.kwargs)
  File "/usr/local/lib/python3.10/site-packages/scrapli/transport/plugins/system/transport.py", line 165, in read
    raise ScrapliConnectionError(msg) from exc
scrapli.exceptions.ScrapliConnectionError: encountered EOF reading from transport; typically means the device closed the connection

2023-01-26 10:46:20,361 -  nornir.core -     INFO -        run() - Running task 'send_command' with args {'command': 'show run'} on 1 hosts
2023-01-26 10:46:20,637 - nornir.core.task -    ERROR -      start() - Host 'cat9k-test-ztp': task 'send_command' failed with traceback:
Traceback (most recent call last):
  File "/usr/local/lib/python3.10/site-packages/scrapli/transport/plugins/system/transport.py", line 158, in read
    buf = self.session.read(65535)
  File "/usr/local/lib/python3.10/site-packages/scrapli/transport/plugins/system/ptyprocess.py", line 496, in read
    raise EOFError("End Of File (EOF). Empty string style platform.")
EOFError: End Of File (EOF). Empty string style platform.

The above exception was the direct cause of the following exception:

Traceback (most recent call last):
  File "/usr/local/lib/python3.10/site-packages/nornir/core/task.py", line 99, in start
    r = self.task(self, **self.params)
  File "/usr/local/lib/python3.10/site-packages/nornir_scrapli/tasks/core/send_command.py", line 36, in send_command
    scrapli_conn = task.host.get_connection("scrapli", task.nornir.config)
  File "/usr/local/lib/python3.10/site-packages/nornir/core/inventory.py", line 494, in get_connection
    self.open_connection(
  File "/usr/local/lib/python3.10/site-packages/nornir/core/inventory.py", line 546, in open_connection
    conn_obj.open(
  File "/usr/local/lib/python3.10/site-packages/nornir_scrapli/connection.py", line 105, in open
    connection.open()
  File "/usr/local/lib/python3.10/site-packages/scrapli/driver/base/sync_driver.py", line 88, in open
    self.channel.channel_authenticate_ssh(
  File "/usr/local/lib/python3.10/site-packages/scrapli/decorators.py", line 216, in decorate
    return _multiprocessing_timeout(
  File "/usr/local/lib/python3.10/site-packages/scrapli/decorators.py", line 113, in _multiprocessing_timeout
    return future.result()
  File "/usr/local/Cellar/python@3.10/3.10.9/Frameworks/Python.framework/Versions/3.10/lib/python3.10/concurrent/futures/_base.py", line 451, in result
    return self.__get_result()
  File "/usr/local/Cellar/python@3.10/3.10.9/Frameworks/Python.framework/Versions/3.10/lib/python3.10/concurrent/futures/_base.py", line 403, in __get_result
    raise self._exception
  File "/usr/local/Cellar/python@3.10/3.10.9/Frameworks/Python.framework/Versions/3.10/lib/python3.10/concurrent/futures/thread.py", line 58, in run
    result = self.fn(*self.args, **self.kwargs)
  File "/usr/local/lib/python3.10/site-packages/scrapli/channel/sync_channel.py", line 287, in channel_authenticate_ssh
    buf = self.read()
  File "/usr/local/lib/python3.10/site-packages/scrapli/channel/sync_channel.py", line 69, in read
    buf = self.transport.read()
  File "/usr/local/lib/python3.10/site-packages/scrapli/decorators.py", line 216, in decorate
    return _multiprocessing_timeout(
  File "/usr/local/lib/python3.10/site-packages/scrapli/decorators.py", line 113, in _multiprocessing_timeout
    return future.result()
  File "/usr/local/Cellar/python@3.10/3.10.9/Frameworks/Python.framework/Versions/3.10/lib/python3.10/concurrent/futures/_base.py", line 451, in result
    return self.__get_result()
  File "/usr/local/Cellar/python@3.10/3.10.9/Frameworks/Python.framework/Versions/3.10/lib/python3.10/concurrent/futures/_base.py", line 403, in __get_result
    raise self._exception
  File "/usr/local/Cellar/python@3.10/3.10.9/Frameworks/Python.framework/Versions/3.10/lib/python3.10/concurrent/futures/thread.py", line 58, in run
    result = self.fn(*self.args, **self.kwargs)
  File "/usr/local/lib/python3.10/site-packages/scrapli/transport/plugins/system/transport.py", line 165, in read
    raise ScrapliConnectionError(msg) from exc
scrapli.exceptions.ScrapliConnectionError: encountered EOF reading from transport; typically means the device closed the connection

2023-01-26 10:47:46,324 -  nornir.core -     INFO -        run() - Running task 'send_command' with args {'command': 'show version'} on 1 hosts
2023-01-26 10:47:46,368 - nornir.core.task -    ERROR -      start() - Host 'cat9k-test-ztp': task 'send_command' failed with traceback:
Traceback (most recent call last):
  File "/usr/local/lib/python3.10/site-packages/scrapli/transport/plugins/system/transport.py", line 158, in read
    buf = self.session.read(65535)
  File "/usr/local/lib/python3.10/site-packages/scrapli/transport/plugins/system/ptyprocess.py", line 496, in read
    raise EOFError("End Of File (EOF). Empty string style platform.")
EOFError: End Of File (EOF). Empty string style platform.

The above exception was the direct cause of the following exception:

Traceback (most recent call last):
  File "/usr/local/lib/python3.10/site-packages/nornir/core/task.py", line 99, in start
    r = self.task(self, **self.params)
  File "/usr/local/lib/python3.10/site-packages/nornir_scrapli/tasks/core/send_command.py", line 36, in send_command
    scrapli_conn = task.host.get_connection("scrapli", task.nornir.config)
  File "/usr/local/lib/python3.10/site-packages/nornir/core/inventory.py", line 494, in get_connection
    self.open_connection(
  File "/usr/local/lib/python3.10/site-packages/nornir/core/inventory.py", line 546, in open_connection
    conn_obj.open(
  File "/usr/local/lib/python3.10/site-packages/nornir_scrapli/connection.py", line 105, in open
    connection.open()
  File "/usr/local/lib/python3.10/site-packages/scrapli/driver/base/sync_driver.py", line 88, in open
    self.channel.channel_authenticate_ssh(
  File "/usr/local/lib/python3.10/site-packages/scrapli/decorators.py", line 216, in decorate
    return _multiprocessing_timeout(
  File "/usr/local/lib/python3.10/site-packages/scrapli/decorators.py", line 113, in _multiprocessing_timeout
    return future.result()
  File "/usr/local/Cellar/python@3.10/3.10.9/Frameworks/Python.framework/Versions/3.10/lib/python3.10/concurrent/futures/_base.py", line 451, in result
    return self.__get_result()
  File "/usr/local/Cellar/python@3.10/3.10.9/Frameworks/Python.framework/Versions/3.10/lib/python3.10/concurrent/futures/_base.py", line 403, in __get_result
    raise self._exception
  File "/usr/local/Cellar/python@3.10/3.10.9/Frameworks/Python.framework/Versions/3.10/lib/python3.10/concurrent/futures/thread.py", line 58, in run
    result = self.fn(*self.args, **self.kwargs)
  File "/usr/local/lib/python3.10/site-packages/scrapli/channel/sync_channel.py", line 287, in channel_authenticate_ssh
    buf = self.read()
  File "/usr/local/lib/python3.10/site-packages/scrapli/channel/sync_channel.py", line 69, in read
    buf = self.transport.read()
  File "/usr/local/lib/python3.10/site-packages/scrapli/decorators.py", line 216, in decorate
    return _multiprocessing_timeout(
  File "/usr/local/lib/python3.10/site-packages/scrapli/decorators.py", line 113, in _multiprocessing_timeout
    return future.result()
  File "/usr/local/Cellar/python@3.10/3.10.9/Frameworks/Python.framework/Versions/3.10/lib/python3.10/concurrent/futures/_base.py", line 451, in result
    return self.__get_result()
  File "/usr/local/Cellar/python@3.10/3.10.9/Frameworks/Python.framework/Versions/3.10/lib/python3.10/concurrent/futures/_base.py", line 403, in __get_result
    raise self._exception
  File "/usr/local/Cellar/python@3.10/3.10.9/Frameworks/Python.framework/Versions/3.10/lib/python3.10/concurrent/futures/thread.py", line 58, in run
    result = self.fn(*self.args, **self.kwargs)
  File "/usr/local/lib/python3.10/site-packages/scrapli/transport/plugins/system/transport.py", line 165, in read
    raise ScrapliConnectionError(msg) from exc
scrapli.exceptions.ScrapliConnectionError: encountered EOF reading from transport; typically means the device closed the connection

2023-01-26 11:05:26,298 -  nornir.core -     INFO -        run() - Running task 'send_command' with args {'command': 'show version'} on 1 hosts
2023-01-26 11:06:14,233 -  nornir.core -     INFO -        run() - Running task 'send_command' with args {'command': 'show version'} on 1 hosts
2023-01-26 11:06:14,316 - nornir.core.task -    ERROR -      start() - Host 'cat9k-test-ztp': task 'send_command' failed with traceback:
Traceback (most recent call last):
  File "/usr/local/lib/python3.10/site-packages/scrapli/transport/plugins/system/transport.py", line 158, in read
    buf = self.session.read(65535)
  File "/usr/local/lib/python3.10/site-packages/scrapli/transport/plugins/system/ptyprocess.py", line 496, in read
    raise EOFError("End Of File (EOF). Empty string style platform.")
EOFError: End Of File (EOF). Empty string style platform.

The above exception was the direct cause of the following exception:

Traceback (most recent call last):
  File "/usr/local/lib/python3.10/site-packages/nornir/core/task.py", line 99, in start
    r = self.task(self, **self.params)
  File "/usr/local/lib/python3.10/site-packages/nornir_scrapli/tasks/core/send_command.py", line 36, in send_command
    scrapli_conn = task.host.get_connection("scrapli", task.nornir.config)
  File "/usr/local/lib/python3.10/site-packages/nornir/core/inventory.py", line 494, in get_connection
    self.open_connection(
  File "/usr/local/lib/python3.10/site-packages/nornir/core/inventory.py", line 546, in open_connection
    conn_obj.open(
  File "/usr/local/lib/python3.10/site-packages/nornir_scrapli/connection.py", line 105, in open
    connection.open()
  File "/usr/local/lib/python3.10/site-packages/scrapli/driver/base/sync_driver.py", line 88, in open
    self.channel.channel_authenticate_ssh(
  File "/usr/local/lib/python3.10/site-packages/scrapli/decorators.py", line 216, in decorate
    return _multiprocessing_timeout(
  File "/usr/local/lib/python3.10/site-packages/scrapli/decorators.py", line 113, in _multiprocessing_timeout
    return future.result()
  File "/usr/local/Cellar/python@3.10/3.10.9/Frameworks/Python.framework/Versions/3.10/lib/python3.10/concurrent/futures/_base.py", line 451, in result
    return self.__get_result()
  File "/usr/local/Cellar/python@3.10/3.10.9/Frameworks/Python.framework/Versions/3.10/lib/python3.10/concurrent/futures/_base.py", line 403, in __get_result
    raise self._exception
  File "/usr/local/Cellar/python@3.10/3.10.9/Frameworks/Python.framework/Versions/3.10/lib/python3.10/concurrent/futures/thread.py", line 58, in run
    result = self.fn(*self.args, **self.kwargs)
  File "/usr/local/lib/python3.10/site-packages/scrapli/channel/sync_channel.py", line 287, in channel_authenticate_ssh
    buf = self.read()
  File "/usr/local/lib/python3.10/site-packages/scrapli/channel/sync_channel.py", line 69, in read
    buf = self.transport.read()
  File "/usr/local/lib/python3.10/site-packages/scrapli/decorators.py", line 216, in decorate
    return _multiprocessing_timeout(
  File "/usr/local/lib/python3.10/site-packages/scrapli/decorators.py", line 113, in _multiprocessing_timeout
    return future.result()
  File "/usr/local/Cellar/python@3.10/3.10.9/Frameworks/Python.framework/Versions/3.10/lib/python3.10/concurrent/futures/_base.py", line 451, in result
    return self.__get_result()
  File "/usr/local/Cellar/python@3.10/3.10.9/Frameworks/Python.framework/Versions/3.10/lib/python3.10/concurrent/futures/_base.py", line 403, in __get_result
    raise self._exception
  File "/usr/local/Cellar/python@3.10/3.10.9/Frameworks/Python.framework/Versions/3.10/lib/python3.10/concurrent/futures/thread.py", line 58, in run
    result = self.fn(*self.args, **self.kwargs)
  File "/usr/local/lib/python3.10/site-packages/scrapli/transport/plugins/system/transport.py", line 165, in read
    raise ScrapliConnectionError(msg) from exc
scrapli.exceptions.ScrapliConnectionError: encountered EOF reading from transport; typically means the device closed the connection

2023-01-26 11:19:57,547 -  nornir.core -     INFO -        run() - Running task 'send_command' with args {'command': 'show version'} on 2 hosts
2023-01-26 11:19:57,551 - nornir.core.task -    ERROR -      start() - Host 'devices': task 'send_command' failed with traceback:
Traceback (most recent call last):
  File "/usr/local/lib/python3.10/site-packages/nornir/core/task.py", line 99, in start
    r = self.task(self, **self.params)
  File "/usr/local/lib/python3.10/site-packages/nornir_scrapli/tasks/core/send_command.py", line 36, in send_command
    scrapli_conn = task.host.get_connection("scrapli", task.nornir.config)
  File "/usr/local/lib/python3.10/site-packages/nornir/core/inventory.py", line 494, in get_connection
    self.open_connection(
  File "/usr/local/lib/python3.10/site-packages/nornir/core/inventory.py", line 546, in open_connection
    conn_obj.open(
  File "/usr/local/lib/python3.10/site-packages/nornir_scrapli/connection.py", line 88, in open
    raise NornirScrapliInvalidPlatform(
nornir_scrapli.exceptions.NornirScrapliInvalidPlatform: 'platform' not provided in inventory for host `None`

2023-01-26 11:19:57,551 - nornir.core.task -    ERROR -      start() - Host 'testbed': task 'send_command' failed with traceback:
Traceback (most recent call last):
  File "/usr/local/lib/python3.10/site-packages/nornir/core/task.py", line 99, in start
    r = self.task(self, **self.params)
  File "/usr/local/lib/python3.10/site-packages/nornir_scrapli/tasks/core/send_command.py", line 36, in send_command
    scrapli_conn = task.host.get_connection("scrapli", task.nornir.config)
  File "/usr/local/lib/python3.10/site-packages/nornir/core/inventory.py", line 494, in get_connection
    self.open_connection(
  File "/usr/local/lib/python3.10/site-packages/nornir/core/inventory.py", line 546, in open_connection
    conn_obj.open(
  File "/usr/local/lib/python3.10/site-packages/nornir_scrapli/connection.py", line 88, in open
    raise NornirScrapliInvalidPlatform(
nornir_scrapli.exceptions.NornirScrapliInvalidPlatform: 'platform' not provided in inventory for host `None`

2023-01-26 11:24:50,396 -  nornir.core -     INFO -        run() - Running task 'send_command' with args {'command': 'show version'} on 1 hosts
2023-01-26 11:24:55,278 - nornir.core.task -    ERROR -      start() - Host 'csr1000v-1': task 'send_command' failed with traceback:
Traceback (most recent call last):
  File "/usr/local/lib/python3.10/site-packages/nornir/core/task.py", line 99, in start
    r = self.task(self, **self.params)
  File "/usr/local/lib/python3.10/site-packages/nornir_scrapli/tasks/core/send_command.py", line 36, in send_command
    scrapli_conn = task.host.get_connection("scrapli", task.nornir.config)
  File "/usr/local/lib/python3.10/site-packages/nornir/core/inventory.py", line 494, in get_connection
    self.open_connection(
  File "/usr/local/lib/python3.10/site-packages/nornir/core/inventory.py", line 546, in open_connection
    conn_obj.open(
  File "/usr/local/lib/python3.10/site-packages/nornir_scrapli/connection.py", line 105, in open
    connection.open()
  File "/usr/local/lib/python3.10/site-packages/scrapli/driver/base/sync_driver.py", line 88, in open
    self.channel.channel_authenticate_ssh(
  File "/usr/local/lib/python3.10/site-packages/scrapli/decorators.py", line 216, in decorate
    return _multiprocessing_timeout(
  File "/usr/local/lib/python3.10/site-packages/scrapli/decorators.py", line 113, in _multiprocessing_timeout
    return future.result()
  File "/usr/local/Cellar/python@3.10/3.10.9/Frameworks/Python.framework/Versions/3.10/lib/python3.10/concurrent/futures/_base.py", line 451, in result
    return self.__get_result()
  File "/usr/local/Cellar/python@3.10/3.10.9/Frameworks/Python.framework/Versions/3.10/lib/python3.10/concurrent/futures/_base.py", line 403, in __get_result
    raise self._exception
  File "/usr/local/Cellar/python@3.10/3.10.9/Frameworks/Python.framework/Versions/3.10/lib/python3.10/concurrent/futures/thread.py", line 58, in run
    result = self.fn(*self.args, **self.kwargs)
  File "/usr/local/lib/python3.10/site-packages/scrapli/channel/sync_channel.py", line 302, in channel_authenticate_ssh
    raise ScrapliAuthenticationFailed(msg)
scrapli.exceptions.ScrapliAuthenticationFailed: password prompt seen more than once, assuming auth failed

2023-01-26 11:26:51,823 -  nornir.core -     INFO -        run() - Running task 'send_command' with args {'command': 'show version'} on 1 hosts
2023-01-26 11:26:56,913 - nornir.core.task -    ERROR -      start() - Host 'csr1000v-1': task 'send_command' failed with traceback:
Traceback (most recent call last):
  File "/usr/local/lib/python3.10/site-packages/nornir/core/task.py", line 99, in start
    r = self.task(self, **self.params)
  File "/usr/local/lib/python3.10/site-packages/nornir_scrapli/tasks/core/send_command.py", line 36, in send_command
    scrapli_conn = task.host.get_connection("scrapli", task.nornir.config)
  File "/usr/local/lib/python3.10/site-packages/nornir/core/inventory.py", line 494, in get_connection
    self.open_connection(
  File "/usr/local/lib/python3.10/site-packages/nornir/core/inventory.py", line 546, in open_connection
    conn_obj.open(
  File "/usr/local/lib/python3.10/site-packages/nornir_scrapli/connection.py", line 105, in open
    connection.open()
  File "/usr/local/lib/python3.10/site-packages/scrapli/driver/base/sync_driver.py", line 88, in open
    self.channel.channel_authenticate_ssh(
  File "/usr/local/lib/python3.10/site-packages/scrapli/decorators.py", line 216, in decorate
    return _multiprocessing_timeout(
  File "/usr/local/lib/python3.10/site-packages/scrapli/decorators.py", line 113, in _multiprocessing_timeout
    return future.result()
  File "/usr/local/Cellar/python@3.10/3.10.9/Frameworks/Python.framework/Versions/3.10/lib/python3.10/concurrent/futures/_base.py", line 451, in result
    return self.__get_result()
  File "/usr/local/Cellar/python@3.10/3.10.9/Frameworks/Python.framework/Versions/3.10/lib/python3.10/concurrent/futures/_base.py", line 403, in __get_result
    raise self._exception
  File "/usr/local/Cellar/python@3.10/3.10.9/Frameworks/Python.framework/Versions/3.10/lib/python3.10/concurrent/futures/thread.py", line 58, in run
    result = self.fn(*self.args, **self.kwargs)
  File "/usr/local/lib/python3.10/site-packages/scrapli/channel/sync_channel.py", line 302, in channel_authenticate_ssh
    raise ScrapliAuthenticationFailed(msg)
scrapli.exceptions.ScrapliAuthenticationFailed: password prompt seen more than once, assuming auth failed

2023-01-26 11:28:04,886 -  nornir.core -     INFO -        run() - Running task 'send_command' with args {'command': 'show version'} on 1 hosts
2023-01-26 11:28:19,923 - nornir.core.task -    ERROR -      start() - Host 'csr1000v-1': task 'send_command' failed with traceback:
Traceback (most recent call last):
  File "/usr/local/lib/python3.10/site-packages/nornir/core/task.py", line 99, in start
    r = self.task(self, **self.params)
  File "/usr/local/lib/python3.10/site-packages/nornir_scrapli/tasks/core/send_command.py", line 36, in send_command
    scrapli_conn = task.host.get_connection("scrapli", task.nornir.config)
  File "/usr/local/lib/python3.10/site-packages/nornir/core/inventory.py", line 494, in get_connection
    self.open_connection(
  File "/usr/local/lib/python3.10/site-packages/nornir/core/inventory.py", line 546, in open_connection
    conn_obj.open(
  File "/usr/local/lib/python3.10/site-packages/nornir_scrapli/connection.py", line 105, in open
    connection.open()
  File "/usr/local/lib/python3.10/site-packages/scrapli/driver/base/sync_driver.py", line 88, in open
    self.channel.channel_authenticate_ssh(
  File "/usr/local/lib/python3.10/site-packages/scrapli/decorators.py", line 216, in decorate
    return _multiprocessing_timeout(
  File "/usr/local/lib/python3.10/site-packages/scrapli/decorators.py", line 113, in _multiprocessing_timeout
    return future.result()
  File "/usr/local/Cellar/python@3.10/3.10.9/Frameworks/Python.framework/Versions/3.10/lib/python3.10/concurrent/futures/_base.py", line 451, in result
    return self.__get_result()
  File "/usr/local/Cellar/python@3.10/3.10.9/Frameworks/Python.framework/Versions/3.10/lib/python3.10/concurrent/futures/_base.py", line 403, in __get_result
    raise self._exception
  File "/usr/local/Cellar/python@3.10/3.10.9/Frameworks/Python.framework/Versions/3.10/lib/python3.10/concurrent/futures/thread.py", line 58, in run
    result = self.fn(*self.args, **self.kwargs)
  File "/usr/local/lib/python3.10/site-packages/scrapli/channel/sync_channel.py", line 290, in channel_authenticate_ssh
    self._ssh_message_handler(output=authenticate_buf)
  File "/usr/local/lib/python3.10/site-packages/scrapli/channel/base_channel.py", line 432, in _ssh_message_handler
    raise ScrapliAuthenticationFailed(msg)
scrapli.exceptions.ScrapliAuthenticationFailed: Timed out connecting to host

2023-01-26 11:32:59,540 -  nornir.core -     INFO -        run() - Running task 'send_command' with args {'command': 'show version'} on 1 hosts
2023-01-26 11:32:59,547 - nornir.core.task -    ERROR -      start() - Host 'csr1000v-1': task 'send_command' failed with traceback:
Traceback (most recent call last):
  File "/usr/local/lib/python3.10/site-packages/scrapli/factory.py", line 157, in _get_community_platform_details
    scrapli_community_platform = importlib.import_module(
  File "/usr/local/Cellar/python@3.10/3.10.9/Frameworks/Python.framework/Versions/3.10/lib/python3.10/importlib/__init__.py", line 126, in import_module
    return _bootstrap._gcd_import(name[level:], package, level)
  File "<frozen importlib._bootstrap>", line 1050, in _gcd_import
  File "<frozen importlib._bootstrap>", line 1027, in _find_and_load
  File "<frozen importlib._bootstrap>", line 1004, in _find_and_load_unlocked
ModuleNotFoundError: No module named 'scrapli_community.iosxe'

The above exception was the direct cause of the following exception:

Traceback (most recent call last):
  File "/usr/local/lib/python3.10/site-packages/nornir_scrapli/connection.py", line 98, in open
    connection = Scrapli(**parameters, platform=final_platform)
  File "/usr/local/lib/python3.10/site-packages/scrapli/factory.py", line 497, in __new__
    final_driver, additional_kwargs = cls._get_driver(platform=platform, variant=variant)
  File "/usr/local/lib/python3.10/site-packages/scrapli/factory.py", line 326, in _get_driver
    final_driver, additional_kwargs = cls._get_community_driver(
  File "/usr/local/lib/python3.10/site-packages/scrapli/factory.py", line 288, in _get_community_driver
    platform_details = _get_community_platform_details(
  File "/usr/local/lib/python3.10/site-packages/scrapli/factory.py", line 168, in _get_community_platform_details
    raise ScrapliModuleNotFound(warning) from exc
scrapli.exceptions.ScrapliModuleNotFound: 

************************************************************************************** Module not found! **************************************************************************************
          Scrapli Community platform 'iosxe` not found!
To resolve this issue, ensure you have the correct platform name, and that a scrapli  community platform of that name exists!          
***********************************************************************************************************************************************************************************************


The above exception was the direct cause of the following exception:

Traceback (most recent call last):
  File "/usr/local/lib/python3.10/site-packages/nornir/core/task.py", line 99, in start
    r = self.task(self, **self.params)
  File "/usr/local/lib/python3.10/site-packages/nornir_scrapli/tasks/core/send_command.py", line 36, in send_command
    scrapli_conn = task.host.get_connection("scrapli", task.nornir.config)
  File "/usr/local/lib/python3.10/site-packages/nornir/core/inventory.py", line 494, in get_connection
    self.open_connection(
  File "/usr/local/lib/python3.10/site-packages/nornir/core/inventory.py", line 546, in open_connection
    conn_obj.open(
  File "/usr/local/lib/python3.10/site-packages/nornir_scrapli/connection.py", line 100, in open
    raise NornirScrapliInvalidPlatform(
nornir_scrapli.exceptions.NornirScrapliInvalidPlatform: Provided platform `iosxe` is not a valid scrapli or napalm platform, or is not a valid scrapli-community platform.

